Workbook

Sheet Read me
A1: ISO 14971 Risk File Toolkit
A2: Companion to the workshop 'Risk Management (ISO 14971): aligning risk files with EU MDR and FDA expectations'
A4: Purpose | B4: A working skeleton of a risk management file that is traceable end to end: every hazard reaches a harm, every unacceptable risk reaches a control, every control reaches a verification of implementation AND a verification of effectiveness, and every residual risk reaches either an acceptability decision or a benefit-risk record.
A5: Why it is built this way | B5: Notified bodies and FDA investigators do not read a risk file to see whether it exists. They pull one hazard and walk it: to the design input, to the verification record, to the labelling, to the complaint data. The columns here are the walk. If a column is empty, that is where the deficiency is written.
A7: How to use it | B7: 1. Fill in 'RM Plan' first. Clause 4.4 requires the plan to define the acceptability criteria BEFORE the analysis. A file whose criteria were written after the risk table is the single most common finding in this area.
B8: 2. Edit 'Scales'. The severity scale, the two probability scales, the P1 x P2 combination table and the acceptability matrix in this workbook are examples. Replace them with your own and record the rationale.
B9: 3. Work 'Hazard Analysis' left to right, one row per hazardous situation (not one row per hazard). The initial and residual risk columns are formulas; do not overwrite them.
B10: 4. Every risk control gets a row on 'Risk Controls' with both verification references. Implementation and effectiveness are two separate records under Clause 7.2.
B11: 5. Residual risks that the criteria do not accept and that cannot be reduced further go to 'Benefit-Risk' under Clause 7.4 or Clause 8.
B12: 6. 'Prod & Post-Prod' is Clause 10. It is the sheet that makes the file living rather than historical, and it is the sheet auditors find empty.
B13: 7. 'RM File Index' is the Clause 4.5 index. 'Dashboard' tells you what is still missing.
A15: Cells to fill in | B15: Every cell with a pale yellow fill is an input. Unshaded cells carry reference data or formulas.
A16: Formula columns | B16: 'Hazard Analysis' columns L to O and U to X; the checks on 'Risk Controls'; every figure on 'Dashboard'; the completeness line on 'RM File Index'. These recalculate from your inputs.
A18: Clause map | B18: RM Plan = 4.4. Scales = 4.4 d). Hazard Analysis = 5.4 and 5.5 (analysis), 6 (evaluation), 7.1 (control option), 7.3 (residual risk evaluation), 7.6 (completeness). Risk Controls = 7.1, 7.2 and 7.5. Residual Risk = 8. Benefit-Risk = 7.4 and 8. Prod & Post-Prod = 10.1 to 10.4. RM File Index = 4.5.
A19: Clause 7 in full | B19: 7.1 Risk control option analysis; 7.2 Implementation of risk control measures; 7.3 Residual risk evaluation; 7.4 Benefit-risk analysis; 7.5 Risks arising from risk control measures; 7.6 Completeness of risk control. Clause 7 runs to 7.6. Note that Clause 6 routes an acceptable risk straight to 7.6 and treats the estimated risk as the residual risk, so 7.6 applies to every hazardous situation, acceptable or not.
A21: One row per hazardous situation | B21: ISO 14971:2019 Clause 5.4 asks for the foreseeable sequences of events that can lead a hazard to a hazardous situation. A single hazard (for example 'energy - electrical') produces several hazardous situations by several sequences, and each carries its own probability. Collapsing them into one row is what makes a probability estimate unjustifiable.
A22: P1 and P2 | B22: The probability of harm is decomposed into P1, the probability of the hazardous situation arising, and P2, the probability that the hazardous situation leads to the harm. ISO 14971:2019 Annex C.5 and ISO/TR 24971:2020 Clause 5.5 describe the decomposition. The combination table on 'Scales' is derived from the decade midpoints of the two scales; the derivation is shown there so a reviewer can audit it.
A23: Acceptable is not the finish line | B23: The matrix produces 'Acceptable' or 'Not acceptable' against the example criteria. That is not the whole EU test. MDR Annex I point 4 requires risk control measures in a fixed order of priority, and point 2 defines the only permitted limit on how far you must go: reduction of risks as far as possible means reduction without adversely affecting the benefit-risk ratio. Cost is not in that sentence. So an 'Acceptable' verdict does not end the obligation to consider further risk control - record why no further control was practicable.
A24: AFAP is not ALARP | B24: ALARP - as low as reasonably practicable - admits economic impact into the judgement. The MDR does not: the word ALARP does not appear in the Regulation, nor does any reference to economic considerations, and the recital of Directive 93/42/EEC that allowed 'technical and economical considerations' was not carried into the MDR. ISO/TR 24971:2020 Annex C is where the choice between ALARP, AFAP, ALARA and ALAP is actually discussed, as guidance on the Clause 4.2 policy.
A25: What Annex ZA does and does not give you | B25: EN ISO 14971:2019/A11:2021 replaces the European foreword and adds Annexes ZA (MDR) and ZB (IVDR). It does not change the normative text of ISO 14971:2019. Annex ZA is a correspondence table, not a list of deviations: the seven content deviations people still cite belong to the withdrawn EN ISO 14971:2012. And the table is narrow - it addresses MDR Annex I Chapter I points 3, 4, 5, 8 and 9. Points 1, 2 and 7, and the whole of Chapters II and III, are not listed as covered, so conformity to the standard buys you no presumption of conformity with the benefit-risk requirement in point 1 or the AFAP definition in point 2. You argue those from the Regulation.
A26: No middle band | B26: ISO 14971:2019 does not use a three-region ALARP matrix. If your matrix has an amber 'acceptable with justification' band carried over from the 2007 edition, expect to be asked which clause it implements.
A28: Sheets | B28: Read me | RM Plan | Scales | Hazard Analysis | Risk Controls | Residual Risk | Benefit-Risk | Prod & Post-Prod | RM File Index | Dashboard
A30: Worked example | B30: The 16 example rows describe a programmable ambulatory infusion pump for home use with a single-use administration set. They are written to be argued with in the workshop, not copied. Two rows contain deliberate defects; the facilitator guide names them.
... A38: Prepared by | B38: Elder Consulting, LLC. Workshop material; not legal or regulatory advice.

Sheet RM Plan
A1: Risk management plan: required contents
A2: ISO 14971:2019 Clause 4.4 a) to g), plus the contents EU MDR and FDA submissions expect to find. Clause 4.4 requires the plan to be part of the risk management file.
A4: # | B4: Required content | C4: What a reviewer looks for | D4: Where it is in your plan | E4: Present? | F4: Owner
A5: 4.4 a) | B5: Scope of the planned risk management activities | C5: The device, its accessories, the life-cycle phases covered, and the parts of the device or process that are excluded with a reason. A plan whose scope is 'the device' cannot be audited.
A6: 4.4 b) | B6: Assignment of responsibilities and authorities | C6: Named roles, not 'the team'. Who may approve a residual risk as acceptable, and who may approve an overall residual risk, are separate authorities and are the two that get asked about.
A7: 4.4 c) | B7: Requirements for review of risk management activities | C7: Which reviews happen, at which milestones, who attends, and what the review has to conclude. This is the hook that produces the Clause 9 report.
A8: 4.4 d) | B8: Criteria for risk acceptability, based on the manufacturer's policy for determining acceptable risk | C8: The criteria themselves, the policy they derive from, and the method for the case where the probability of occurrence of harm cannot be estimated. A file with a matrix and no policy behind it is the single most common deficiency in this clause.
A9: 4.4 d) | B9: Criteria for the case where probability cannot be estimated | C9: ISO 14971:2019 requires the criteria to include how risk is evaluated when probability of occurrence of harm cannot be estimated. In practice this means severity-only evaluation and a stated decision rule. Most plans are silent here.
A10: 4.4 e) | B10: Method to evaluate overall residual risk and the criteria for its acceptability | C10: Overall residual risk is a separate evaluation from the sum of individual risks (Clause 8). The plan must say how it is done and what makes it acceptable, before the answer is known.
A11: 4.4 f) | B11: Activities for verification of the implementation and effectiveness of risk control measures | C11: Two activities, not one, per Clause 7.2. What record proves the control was implemented, and what record proves it works.
A12: 4.4 g) | B12: Activities related to collection and review of relevant production and post-production information | C12: The named information sources, who reviews them, how often, and the trigger that sends a finding back into the risk file. This is the Clause 10 hook and it is the one auditors find missing.
A13: MDR | B13: Link to the risk management system required by Article 10(2) and Annex I point 3 | C13: Annex I point 3 requires the system and sets out the iterative process in sub-points (a) to (f); (a) is the risk management plan itself and (e) to (f) are the production and post-production feedback loop. Article 10(2) is the headline obligation and Article 10(9)(e) puts risk management inside the QMS. Name the procedure, and name where the risk management plan sits relative to the PMS plan (Annex III point 1(b), which requires indicators and threshold values) and the PMCF plan (Annex XIV Part B).
A14: MDR | B14: How the plan addresses GSPRs 1 to 9 and the AFAP obligation | C14: Annex I point 4 sets the order of priority for risk control: (a) safe design and manufacture, (b) protection measures including alarms, (c) information for safety and training, and it closes with 'Manufacturers shall inform users of any residual risks'. Point 2 defines the test: reducing risks as far as possible means reduction without adversely affecting the benefit-risk ratio - not cost. State which of the two you are applying, because Annex ZA of EN ISO 14971:2019/A11:2021 does not list points 1, 2 or 7 among the requirements it covers, so those are argued from the Regulation and not from the standard.
A15: MDR | B15: Method for the benefit-risk determination and its acceptability criteria | C15: Annex I points 1 and 8 require risks and undesirable side-effects to be acceptable when weighed against the benefits. Say how clinical benefit is characterised (nature, magnitude, probability, duration) and against what the residual risk is weighed.
A16: FDA | B16: Integration with the QMS processes FDA inspects | C16: 21 CFR 820.7 incorporates ISO 13485:2016, so risk management is inspected through Clauses 4.1.2 b), 7.1 and the design, purchasing, production and measurement clauses. Say which procedures carry the risk interface, because that is the trail an investigator walks.
... A21: Both | B21: Plan revision control | C21: Clause 4.4 requires changes to the plan to be recorded in the risk management file. A plan at revision 1 alongside a risk table at revision 7 is a finding on its own.

Sheet Scales
A1: Scales, combination table and acceptability criteria
A2: EXAMPLES. ISO 14971:2019 Clause 4.4 d) requires the manufacturer to define its own criteria in the risk management plan. Replace every value on this sheet and record the rationale.
A4: Severity of harm
A5: Level | B5: Label | C5: Description | E5: MDR reporting relevance
A6: 5 | B6: Catastrophic | C6: Results in patient death. | E6: Serious incident (Article 2(65)); reportable
A7: 4 | B7: Critical | C7: Results in permanent impairment of a body function or permanent damage to a body structure, or a life-threatening illness or injury. | E7: Serious incident; reportable
A8: 3 | B8: Serious | C8: Results in injury or impairment requiring professional medical intervention. | E8: Likely a serious deterioration in state of health; assess reportability
A9: 2 | B9: Minor | C9: Results in temporary injury or impairment not requiring professional medical intervention. | E9: Usually not a serious incident; feeds trend reporting
A10: 1 | B10: Negligible | C10: Inconvenience or temporary discomfort. | E10: Not a serious incident; feeds trend reporting
A11: P1 - probability of the hazardous situation arising
A12: Per device per year of use, unless the plan states another basis. State the basis; a band with no basis cannot be defended.
A13: Level | B13: Label | C13: Quantitative band | E13: log10 midpoint used below
A14: 5 | B14: Frequent | C14: greater than or equal to 1 in 1,000 | E14: -2.5
A15: 4 | B15: Probable | C15: 1 in 1,000 to 1 in 10,000 | E15: -3.5
A16: 3 | B16: Occasional | C16: 1 in 10,000 to 1 in 100,000 | E16: -4.5
A17: 2 | B17: Remote | C17: 1 in 100,000 to 1 in 1,000,000 | E17: -5.5
A18: 1 | B18: Improbable | C18: less than 1 in 1,000,000 | E18: -6.5
A20: P2 - conditional probability that the hazardous situation leads to the harm
A21: A conditional probability, so it is dimensionless. It carries the clinical argument: who is exposed, for how long, whether the harm is detectable and reversible, and whether anyone intervenes in time.
A22: Level | B22: Label | C22: Conditional probability band | E22: log10 midpoint used below
A23: 5 | B23: Almost certain | C23: greater than 0.9 | E23: 0
A24: 4 | B24: Likely | C24: 0.1 to 0.9 | E24: -0.7
A25: 3 | B25: Possible | C25: 0.01 to 0.1 | E25: -1.5
A26: 2 | B26: Unlikely | C26: 0.001 to 0.01 | E26: -2.5
A27: 1 | B27: Very unlikely | C27: less than 0.001 | E27: -3.5
A29: Combined probability of harm: P1 x P2
A30: Derived, not asserted. Combined log10 = P1 midpoint + P2 midpoint, banded at -3, -4, -5 and -6. The derivation is shown so a reviewer can audit it; if you change a midpoint, change the table.
A31: P1 \ P2 | B31: P2 = 5 | C31: P2 = 4 | D31: P2 = 3 | E31: P2 = 2 | F31: P2 = 1
A32: P1 = 5 | B32: 5 | C32: 4 | D32: 4 | E32: 3 | F32: 2
A33: P1 = 4 | B33: 4 | C33: 3 | D33: 3 | E33: 2 | F33: 1
A34: P1 = 3 | B34: 3 | C34: 2 | D34: 2 | E34: 1 | F34: 1
A35: P1 = 2 | B35: 2 | C35: 1 | D35: 1 | E35: 1 | F35: 1
A36: P1 = 1 | B36: 1 | C36: 1 | D36: 1 | E36: 1 | F36: 1
A38: Risk acceptability matrix (example criteria)
A39: Two regions only. ISO 14971:2019 does not use a three-region ALARP matrix; an amber 'acceptable with justification' band is a hold-over from the 2007 edition. A 'Not acceptable' verdict routes to further risk control and, if none is practicable, to a benefit-risk analysis under Clause 7.4.
A40: An 'Acceptable' verdict does not end the obligation. MDR Annex I point 4 requires the order of priority to be worked, and point 2 sets the only permitted limit on how far: without adversely affecting the benefit-risk ratio. Record why no further control was practicable.
A41: P \ S | B41: S = 1 | C41: S = 2 | D41: S = 3 | E41: S = 4 | F41: S = 5
A42: P = 5 | B42: Acceptable | C42: Not acceptable | D42: Not acceptable | E42: Not acceptable | F42: Not acceptable
A43: P = 4 | B43: Acceptable | C43: Acceptable | D43: Not acceptable | E43: Not acceptable | F43: Not acceptable
A44: P = 3 | B44: Acceptable | C44: Acceptable | D44: Not acceptable | E44: Not acceptable | F44: Not acceptable
...

Sheet Hazard Analysis
A1: Hazard analysis and risk evaluation
A2: One row per hazardous situation, not per hazard. A single hazard reaches several hazardous situations by several sequences, and each carries its own probability. Columns L to O and U to X are formulas.
A4: ID | B4: Device function or part | C4: Hazard (category) | D4: Foreseeable sequence of events (Clause 5.4) | E4: Hazardous situation (Clause 5.4) | F4: Harm (Clause 5.5) | G4: MDR Annex I GSPR link | H4: P1 init | I4: P2 init | J4: S init | K4: Basis for the estimate (record or source) | L4: P init | M4: Initial risk (formula) | N4: Risk index | O4: Control needed? (formula) | P4: Primary control ID | Q4: Ctrl cat | R4: P1 res | S4: P2 res | T4: S res | U4: P res | V4: Residual risk (formula) | W4: Benefit-risk needed? (formula) | X4: Completeness check (formula) | Y4: New risk from the control? | Z4: Residual risk disclosure (IFU or label ref) | AA4: Status
A5: HZ-01 | B5: Pumping mechanism and administration set | C5: Energy - mechanical (unintended delivery) | D5: Downstream occlusion raises pressure in the compliant administration set; the occlusion clears and the stored volume is released before the pump can decompress the line. | E5: Patient receives a bolus of drug well above the prescribed rate. | F5: Over-infusion: hypotension and respiratory depression. | G5: 1, 4, 14.2(a), 21.1, 21.2 | H5: 4 | I5: 4 | J5: 4 | K5: Complaint trend CT-2025-041; bench test BT-114 (post-occlusion bolus volume). | L5: =IF($H5="","",IF($H5=0,"n/e",INDEX(Scales!$B$32:$F$36,6-$H5,6-$I5))) -> 3 | M5: =IF($L5="","",IF($L5="n/e",IF($J5>=3,"Not acceptable (S only)","Acceptable (S only)"),INDEX(Scales!$B$42:$F$46,6-$L5,$J5))) -> Not acceptable | N5: =IF(OR($L5="",$L5="n/e"),"",$L5*$J5) -> 12 | O5: =IF($M5="","",IF(LEFT($M5,3)="Not","Yes - Clause 7.1","Consider AFAP")) -> Yes - Clause 7.1 | P5: RC-01 | Q5: 1 | R5: 2 | S5: 4 | T5: 4 | U5: =IF($R5="","",IF($R5=0,"n/e",INDEX(Scales!$B$32:$F$36,6-$R5,6-$S5))) -> 1 | V5: =IF($U5="","",IF($U5="n/e",IF($T5>=3,"Not acceptable (S only)","Acceptable (S only)"),INDEX(Scales!$B$42:$F$46,6-$U5,$T5))) -> Acceptable | W5: =IF($V5="","",IF(LEFT($V5,3)="Not","Yes - Clause 7.4","No")) -> No | X5: =IF($A5="","",IF($G5="","GSPR link missing",IF($K5="","Basis for estimate missing",IF(AND(LEFT($O5,3)="Yes",$P5=""),"Risk control missing",IF(AND($P5<>"",COUNTIF('Risk Controls'!$A:$A,$P5)=0),"Control not on Risk Controls",IF(AND($P5<>"",$R5=""),"Residual risk not estimated",IF(AND($P5<>"",COUNTIFS('Risk Controls'!$A:$A,$P5,'Risk Controls'!$H:$H,"<>")=0),"Effectiveness not verified",IF(AND($Q5=3,$Z5=""),"Disclosure reference missing",IF(AND(LEFT($W5,3)="Yes",COUNTIF('Benefit-Risk'!$A:$A,$A5)=0),"Benefit-risk record missing","Complete"))))))))) -> Complete | Y5: Y - see HZ-17 (nuisance alarms) | AA5: Closed
A6: HZ-02 | B6: Administration set and roller clamp | C6: Energy - mechanical (free flow) | D6: User removes the administration set from the pump door without closing the roller clamp; the head height of the reservoir drives gravity flow to the patient. | E6: Patient is exposed to uncontrolled gravity infusion. | F6: Over-infusion: overdose, death. | G6: 1, 4, 5, 21.1, 21.2 | H6: 4 | I6: 5 | J6: 5 | K6: Use-related risk analysis URA-07; formative usability study US-03 (4 of 15 participants). | L6: =IF($H6="","",IF($H6=0,"n/e",INDEX(Scales!$B$32:$F$36,6-$H6,6-$I6))) -> 4 | M6: =IF($L6="","",IF($L6="n/e",IF($J6>=3,"Not acceptable (S only)","Acceptable (S only)"),INDEX(Scales!$B$42:$F$46,6-$L6,$J6))) -> Not acceptable | N6: =IF(OR($L6="",$L6="n/e"),"",$L6*$J6) -> 20 | O6: =IF($M6="","",IF(LEFT($M6,3)="Not","Yes - Clause 7.1","Consider AFAP")) -> Yes - Clause 7.1 | P6: RC-02 | Q6: 1 | R6: 2 | S6: 5 | T6: 5 | U6: =IF($R6="","",IF($R6=0,"n/e",INDEX(Scales!$B$32:$F$36,6-$R6,6-$S6))) -> 2 | V6: =IF($U6="","",IF($U6="n/e",IF($T6>=3,"Not acceptable (S only)","Acceptable (S only)"),INDEX(Scales!$B$42:$F$46,6-$U6,$T6))) -> Not acceptable | W6: =IF($V6="","",IF(LEFT($V6,3)="Not","Yes - Clause 7.4","No")) -> Yes - Clause 7.4 | X6: =IF($A6="","",IF($G6="","GSPR link missing",IF($K6="","Basis for estimate missing",IF(AND(LEFT($O6,3)="Yes",$P6=""),"Risk control missing",IF(AND($P6<>"",COUNTIF('Risk Controls'!$A:$A,$P6)=0),"Control not on Risk Controls",IF(AND($P6<>"",$R6=""),"Residual risk not estimated",IF(AND($P6<>"",COUNTIFS('Risk Controls'!$A:$A,$P6,'Risk Controls'!$H:$H,"<>")=0),"Effectiveness not verified",IF(AND($Q6=3,$Z6=""),"Disclosure reference missing",IF(AND(LEFT($W6,3)="Yes",COUNTIF('Benefit-Risk'!$A:$A,$A6)=0),"Benefit-risk record missing","Complete"))))))))) -> Complete | Y6: N | AA6: Closed
A7: HZ-03 | B7: Air-in-line detector | C7: Energy and materials - air embolism | D7: Reservoir empties; air enters the fluid path; at low flow rates the bubble size stays below the detector's sensitivity threshold and accumulates undetected. | E7: Air bolus present in the venous line. | F7: Air embolism: stroke, death. | G7: 1, 4, 14.2(e), 21.2 | H7: 3 | I7: 3 | J7: 5 | K7: Detector characterisation report DR-22; literature on embolism thresholds by bolus volume. | L7: =IF($H7="","",IF($H7=0,"n/e",INDEX(Scales!$B$32:$F$36,6-$H7,6-$I7))) -> 2 | M7: =IF($L7="","",IF($L7="n/e",IF($J7>=3,"Not acceptable (S only)","Acceptable (S only)"),INDEX(Scales!$B$42:$F$46,6-$L7,$J7))) -> Not acceptable | N7: =IF(OR($L7="",$L7="n/e"),"",$L7*$J7) -> 10 | O7: =IF($M7="","",IF(LEFT($M7,3)="Not","Yes - Clause 7.1","Consider AFAP")) -> Yes - Clause 7.1 | P7: RC-03 | Q7: 2 | R7: 2 | S7: 3 | T7: 5 | U7: =IF($R7="","",IF($R7=0,"n/e",INDEX(Scales!$B$32:$F$36,6-$R7,6-$S7))) -> 1 | V7: =IF($U7="","",IF($U7="n/e",IF($T7>=3,"Not acceptable (S only)","Acceptable (S only)"),INDEX(Scales!$B$42:$F$46,6-$U7,$T7))) -> Not acceptable | W7: =IF($V7="","",IF(LEFT($V7,3)="Not","Yes - Clause 7.4","No")) -> Yes - Clause 7.4 | X7: =IF($A7="","",IF($G7="","GSPR link missing",IF($K7="","Basis for estimate missing",IF(AND(LEFT($O7,3)="Yes",$P7=""),"Risk control missing",IF(AND($P7<>"",COUNTIF('Risk Controls'!$A:$A,$P7)=0),"Control not on Risk Controls",IF(AND($P7<>"",$R7=""),"Residual risk not estimated",IF(AND($P7<>"",COUNTIFS('Risk Controls'!$A:$A,$P7,'Risk Controls'!$H:$H,"<>")=0),"Effectiveness not verified",IF(AND($Q7=3,$Z7=""),"Disclosure reference missing",IF(AND(LEFT($W7,3)="Yes",COUNTIF('Benefit-Risk'!$A:$A,$A7)=0),"Benefit-risk record missing","Complete"))))))))) -> Complete | Y7: N | AA7: Closed
A8: HZ-04 | B8: User interface - rate programming | C8: Use error - data entry | D8: Clinician mis-keys a decimal point and enters ten times the intended rate; the confirmation screen displays the number without the drug and unit context needed to catch it. | E8: Pump is set to deliver ten times the prescribed rate. | F8: Over-infusion: overdose. | G8: 1, 5, 14.6, 21.1, 21.3 | H8: 4 | I8: 4 | J8: 4 | K8: Use-related risk analysis URA-11; summative usability study US-09 to IEC 62366-1. | L8: =IF($H8="","",IF($H8=0,"n/e",INDEX(Scales!$B$32:$F$36,6-$H8,6-$I8))) -> 3 | M8: =IF($L8="","",IF($L8="n/e",IF($J8>=3,"Not acceptable (S only)","Acceptable (S only)"),INDEX(Scales!$B$42:$F$46,6-$L8,$J8))) -> Not acceptable | N8: =IF(OR($L8="",$L8="n/e"),"",$L8*$J8) -> 12 | O8: =IF($M8="","",IF(LEFT($M8,3)="Not","Yes - Clause 7.1","Consider AFAP")) -> Yes - Clause 7.1 | P8: RC-04 | Q8: 2 | R8: 2 | S8: 4 | T8: 4 | U8: =IF($R8="","",IF($R8=0,"n/e",INDEX(Scales!$B$32:$F$36,6-$R8,6-$S8))) -> 1 | V8: =IF($U8="","",IF($U8="n/e",IF($T8>=3,"Not acceptable (S only)","Acceptable (S only)"),INDEX(Scales!$B$42:$F$46,6-$U8,$T8))) -> Acceptable | W8: =IF($V8="","",IF(LEFT($V8,3)="Not","Yes - Clause 7.4","No")) -> No | X8: =IF($A8="","",IF($G8="","GSPR link missing",IF($K8="","Basis for estimate missing",IF(AND(LEFT($O8,3)="Yes",$P8=""),"Risk control missing",IF(AND($P8<>"",COUNTIF('Risk Controls'!$A:$A,$P8)=0),"Control not on Risk Controls",IF(AND($P8<>"",$R8=""),"Residual risk not estimated",IF(AND($P8<>"",COUNTIFS('Risk Controls'!$A:$A,$P8,'Risk Controls'!$H:$H,"<>")=0),"Effectiveness not verified",IF(AND($Q8=3,$Z8=""),"Disclosure reference missing",IF(AND(LEFT($W8,3)="Yes",COUNTIF('Benefit-Risk'!$A:$A,$A8)=0),"Benefit-risk record missing","Complete"))))))))) -> Complete | Y8: Y - see HZ-18 (limit override workaround) | AA8: Open
A9: HZ-05 | B9: Battery and power management | C9: Energy - loss of power | D9: Battery capacity degrades with cycling; the remaining-time indicator is computed from nominal rather than measured capacity, so the pump reaches cut-off earlier than the display predicts. | E9: Therapy is interrupted without usable warning. | F9: Under-infusion: loss of therapy; for a vasoactive drug, haemodynamic collapse. | G9: 1, 4, 18.1, 18.2 | H9: 3 | I9: 4 | J9: 4 | K9: Battery cycle-life test BT-208; field data on service age at failure. | L9: =IF($H9="","",IF($H9=0,"n/e",INDEX(Scales!$B$32:$F$36,6-$H9,6-$I9))) -> 2 | M9: =IF($L9="","",IF($L9="n/e",IF($J9>=3,"Not acceptable (S only)","Acceptable (S only)"),INDEX(Scales!$B$42:$F$46,6-$L9,$J9))) -> Not acceptable | N9: =IF(OR($L9="",$L9="n/e"),"",$L9*$J9) -> 8 | O9: =IF($M9="","",IF(LEFT($M9,3)="Not","Yes - Clause 7.1","Consider AFAP")) -> Yes - Clause 7.1 | P9: RC-05 | Q9: 2 | R9: 2 | S9: 4 | T9: 4 | U9: =IF($R9="","",IF($R9=0,"n/e",INDEX(Scales!$B$32:$F$36,6-$R9,6-$S9))) -> 1 | V9: =IF($U9="","",IF($U9="n/e",IF($T9>=3,"Not acceptable (S only)","Acceptable (S only)"),INDEX(Scales!$B$42:$F$46,6-$U9,$T9))) -> Acceptable | W9: =IF($V9="","",IF(LEFT($V9,3)="Not","Yes - Clause 7.4","No")) -> No | X9: =IF($A9="","",IF($G9="","GSPR link missing",IF($K9="","Basis for estimate missing",IF(AND(LEFT($O9,3)="Yes",$P9=""),"Risk control missing",IF(AND($P9<>"",COUNTIF('Risk Controls'!$A:$A,$P9)=0),"Control not on Risk Controls",IF(AND($P9<>"",$R9=""),"Residual risk not estimated",IF(AND($P9<>"",COUNTIFS('Risk Controls'!$A:$A,$P9,'Risk Controls'!$H:$H,"<>")=0),"Effectiveness not verified",IF(AND($Q9=3,$Z9=""),"Disclosure reference missing",IF(AND(LEFT($W9,3)="Yes",COUNTIF('Benefit-Risk'!$A:$A,$A9)=0),"Benefit-risk record missing","Complete"))))))))) -> Complete | Y9: N | AA9: Closed
A10: HZ-06 | B10: Software - weight-based dose calculation | C10: Information - incorrect output | D10: The unit-conversion routine truncates instead of rounding when patient weight is entered in pounds, so the computed dose is systematically low for some weights. | E10: Pump is set to deliver a dose below the prescription. | F10: Under-infusion: therapeutic failure. | G10: 1, 17.1, 17.2, 21.1 | H10: 2 | I10: 4 | J10: 3 | K10: Software anomaly SA-31; unit test suite UT-dose; code review CR-14 (IEC 62304 Class C). | L10: =IF($H10="","",IF($H10=0,"n/e",INDEX(Scales!$B$32:$F$36,6-$H10,6-$I10))) -> 1 | M10: =IF($L10="","",IF($L10="n/e",IF($J10>=3,"Not acceptable (S only)","Acceptable (S only)"),INDEX(Scales!$B$42:$F$46,6-$L10,$J10))) -> Acceptable | N10: =IF(OR($L10="",$L10="n/e"),"",$L10*$J10) -> 3 | O10: =IF($M10="","",IF(LEFT($M10,3)="Not","Yes - Clause 7.1","Consider AFAP")) -> Consider AFAP | P10: RC-06 | Q10: 1 | R10: 1 | S10: 4 | T10: 3 | U10: =IF($R10="","",IF($R10=0,"n/e",INDEX(Scales!$B$32:$F$36,6-$R10,6-$S10))) -> 1 | V10: =IF($U10="","",IF($U10="n/e",IF($T10>=3,"Not acceptable (S only)","Acceptable (S only)"),INDEX(Scales!$B$42:$F$46,6-$U10,$T10))) -> Acceptable | W10: =IF($V10="","",IF(LEFT($V10,3)="Not","Yes - Clause 7.4","No")) -> No | X10: =IF($A10="","",IF($G10="","GSPR link missing",IF($K10="","Basis for estimate missing",IF(AND(LEFT($O10,3)="Yes",$P10=""),"Risk control missing",IF(AND($P10<>"",COUNTIF('Risk Controls'!$A:$A,$P10)=0),"Control not on Risk Controls",IF(AND($P10<>"",$R10=""),"Residual risk not estimated",IF(AND($P10<>"",COUNTIFS('Risk Controls'!$A:$A,$P10,'Risk Controls'!$H:$H,"<>")=0),"Effectiveness not verified",IF(AND($Q10=3,$Z10=""),"Disclosure reference missing",IF(AND(LEFT($W10,3)="Yes",COUNTIF('Benefit-Risk'!$A:$A,$A10)=0),"Benefit-risk record missing","Complete"))))))))) -> Complete | Y10: N | AA10: Closed
A11: HZ-07 | B11: Wireless drug-library update | C11: Information - security | D11: An update package is accepted over the hospital network without authentication of its origin or integrity, replacing the hard dose limits on every pump that receives it. | E11: Hard dose limits are absent or wrong across a fleet of pumps. | F11: Over-infusion affecting multiple patients. | G11: 1, 14.2(d), 17.2, 17.4, 18.8 | H11: 2 | I11: 3 | J11: 5 | K11: Threat model TM-03; penetration test PT-09; SBOM review. | L11: =IF($H11="","",IF($H11=0,"n/e",INDEX(Scales!$B$32:$F$36,6-$H11,6-$I11))) -> 1 | M11: =IF($L11="","",IF($L11="n/e",IF($J11>=3,"Not acceptable (S only)","Acceptable (S only)"),INDEX(Scales!$B$42:$F$46,6-$L11,$J11))) -> Not acceptable | N11: =IF(OR($L11="",$L11="n/e"),"",$L11*$J11) -> 5 | O11: =IF($M11="","",IF(LEFT($M11,3)="Not","Yes - Clause 7.1","Consider AFAP")) -> Yes - Clause 7.1 | P11: RC-07 | Q11: 1 | R11: 1 | S11: 3 | T11: 5 | U11: =IF($R11="","",IF($R11=0,"n/e",INDEX(Scales!$B$32:$F$36,6-$R11,6-$S11))) -> 1 | V11: =IF($U11="","",IF($U11="n/e",IF($T11>=3,"Not acceptable (S only)","Acceptable (S only)"),INDEX(Scales!$B$42:$F$46,6-$U11,$T11))) -> Not acceptable | W11: =IF($V11="","",IF(LEFT($V11,3)="Not","Yes - Clause 7.4","No")) -> Yes - Clause 7.4 | X11: =IF($A11="","",IF($G11="","GSPR link missing",IF($K11="","Basis for estimate missing",IF(AND(LEFT($O11,3)="Yes",$P11=""),"Risk control missing",IF(AND($P11<>"",COUNTIF('Risk Controls'!$A:$A,$P11)=0),"Control not on Risk Controls",IF(AND($P11<>"",$R11=""),"Residual risk not estimated",IF(AND($P11<>"",COUNTIFS('Risk Controls'!$A:$A,$P11,'Risk Controls'!$H:$H,"<>")=0),"Effectiveness not verified",IF(AND($Q11=3,$Z11=""),"Disclosure reference missing",IF(AND(LEFT($W11,3)="Yes",COUNTIF('Benefit-Risk'!$A:$A,$A11)=0),"Benefit-risk record missing","Complete"))))))))) -> Complete | Y11: N | AA11: Open
A12: HZ-08 | B12: Fluid path sterile barrier | C12: Biological - contamination | D12: Pouch seal strength is specified below what the distribution profile demands; the seal channels in transit and the breach is not visible to the user at the point of use. | E12: Non-sterile fluid path is placed in contact with the bloodstream. | F12: Bloodstream infection: sepsis. | G12: 1, 11.1, 11.4, 11.7 | H12: 2 | I12: 3 | J12: 4 | K12: Package validation PV-05 to ISO 11607-1 and -2; distribution test to ASTM D4169. | L12: =IF($H12="","",IF($H12=0,"n/e",INDEX(Scales!$B$32:$F$36,6-$H12,6-$I12))) -> 1 | M12: =IF($L12="","",IF($L12="n/e",IF($J12>=3,"Not acceptable (S only)","Acceptable (S only)"),INDEX(Scales!$B$42:$F$46,6-$L12,$J12))) -> Acceptable | N12: =IF(OR($L12="",$L12="n/e"),"",$L12*$J12) -> 4 | O12: =IF($M12="","",IF(LEFT($M12,3)="Not","Yes - Clause 7.1","Consider AFAP")) -> Consider AFAP | P12: RC-08 | Q12: 1 | R12: 1 | S12: 3 | T12: 4 | U12: =IF($R12="","",IF($R12=0,"n/e",INDEX(Scales!$B$32:$F$36,6-$R12,6-$S12))) -> 1 | V12: =IF($U12="","",IF($U12="n/e",IF($T12>=3,"Not acceptable (S only)","Acceptable (S only)"),INDEX(Scales!$B$42:$F$46,6-$U12,$T12))) -> Acceptable | W12: =IF($V12="","",IF(LEFT($V12,3)="Not","Yes - Clause 7.4","No")) -> No | X12: =IF($A12="","",IF($G12="","GSPR link missing",IF($K12="","Basis for estimate missing",IF(AND(LEFT($O12,3)="Yes",$P12=""),"Risk control missing",IF(AND($P12<>"",COUNTIF('Risk Controls'!$A:$A,$P12)=0),"Control not on Risk Controls",IF(AND($P12<>"",$R12=""),"Residual risk not estimated",IF(AND($P12<>"",COUNTIFS('Risk Controls'!$A:$A,$P12,'Risk Controls'!$H:$H,"<>")=0),"Effectiveness not verified",IF(AND($Q12=3,$Z12=""),"Disclosure reference missing",IF(AND(LEFT($W12,3)="Yes",COUNTIF('Benefit-Risk'!$A:$A,$A12)=0),"Benefit-risk record missing","Complete"))))))))) -> Complete | Y12: N | AA12: Closed
A13: HZ-09 | B13: Administration set material | C13: Biological - chemical (leachables) | D13: A lipophilic drug is infused over 24 hours through a plasticised PVC set; the plasticiser partitions into the drug solution and is delivered to the patient. | E13: Patient is exposed to the plasticiser above the tolerable intake. | F13: Reproductive toxicity; long latency, not attributable at the time of use. | G13: 1, 10.1, 10.3, 10.4.1, 10.4.2 | H13: 5 | I13: 2 | J13: 3 | K13: Biological evaluation BE-02 to ISO 10993-1; extractables and leachables study EL-06; toxicological risk assessment TRA-03. | L13: =IF($H13="","",IF($H13=0,"n/e",INDEX(Scales!$B$32:$F$36,6-$H13,6-$I13))) -> 3 | M13: =IF($L13="","",IF($L13="n/e",IF($J13>=3,"Not acceptable (S only)","Acceptable (S only)"),INDEX(Scales!$B$42:$F$46,6-$L13,$J13))) -> Not acceptable | N13: =IF(OR($L13="",$L13="n/e"),"",$L13*$J13) -> 9 | O13: =IF($M13="","",IF(LEFT($M13,3)="Not","Yes - Clause 7.1","Consider AFAP")) -> Yes - Clause 7.1 | P13: RC-09 | Q13: 1 | R13: 1 | S13: 2 | T13: 3 | U13: =IF($R13="","",IF($R13=0,"n/e",INDEX(Scales!$B$32:$F$36,6-$R13,6-$S13))) -> 1 | V13: =IF($U13="","",IF($U13="n/e",IF($T13>=3,"Not acceptable (S only)","Acceptable (S only)"),INDEX(Scales!$B$42:$F$46,6-$U13,$T13))) -> Acceptable | W13: =IF($V13="","",IF(LEFT($V13,3)="Not","Yes - Clause 7.4","No")) -> No | X13: =IF($A13="","",IF($G13="","GSPR link missing",IF($K13="","Basis for estimate missing",IF(AND(LEFT($O13,3)="Yes",$P13=""),"Risk control missing",IF(AND($P13<>"",COUNTIF('Risk Controls'!$A:$A,$P13)=0),"Control not on Risk Controls",IF(AND($P13<>"",$R13=""),"Residual risk not estimated",IF(AND($P13<>"",COUNTIFS('Risk Controls'!$A:$A,$P13,'Risk Controls'!$H:$H,"<>")=0),"Effectiveness not verified",IF(AND($Q13=3,$Z13=""),"Disclosure reference missing",IF(AND(LEFT($W13,3)="Yes",COUNTIF('Benefit-Risk'!$A:$A,$A13)=0),"Benefit-risk record missing","Complete"))))))))) -> Complete | Y13: N | AA13: Closed
A14: HZ-10 | B14: Alarm system - audible alarm | C14: Information - alarm not perceived | D14: The device is used at home overnight; the occlusion alarm at the specified sound pressure level is masked by ambient noise and the sleeping patient does not wake. | E14: An occlusion persists undetected for several hours. | F14: Under-infusion: loss of therapy. | G14: 1, 5, 18.4, 21.2, 22.1 | H14: 3 | I14: 4 | J14: 3 | K14: Alarm audibility test AT-04 to IEC 60601-1-8; home-use environment characterisation HE-02. | L14: =IF($H14="","",IF($H14=0,"n/e",INDEX(Scales!$B$32:$F$36,6-$H14,6-$I14))) -> 2 | M14: =IF($L14="","",IF($L14="n/e",IF($J14>=3,"Not acceptable (S only)","Acceptable (S only)"),INDEX(Scales!$B$42:$F$46,6-$L14,$J14))) -> Acceptable | N14: =IF(OR($L14="",$L14="n/e"),"",$L14*$J14) -> 6 | O14: =IF($M14="","",IF(LEFT($M14,3)="Not","Yes - Clause 7.1","Consider AFAP")) -> Consider AFAP | P14: RC-10 | Q14: 2 | R14: 2 | S14: 3 | T14: 3 | U14: =IF($R14="","",IF($R14=0,"n/e",INDEX(Scales!$B$32:$F$36,6-$R14,6-$S14))) -> 1 | V14: =IF($U14="","",IF($U14="n/e",IF($T14>=3,"Not acceptable (S only)","Acceptable (S only)"),INDEX(Scales!$B$42:$F$46,6-$U14,$T14))) -> Acceptable | W14: =IF($V14="","",IF(LEFT($V14,3)="Not","Yes - Clause 7.4","No")) -> No | X14: =IF($A14="","",IF($G14="","GSPR link missing",IF($K14="","Basis for estimate missing",IF(AND(LEFT($O14,3)="Yes",$P14=""),"Risk control missing",IF(AND($P14<>"",COUNTIF('Risk Controls'!$A:$A,$P14)=0),"Control not on Risk Controls",IF(AND($P14<>"",$R14=""),"Residual risk not estimated",IF(AND($P14<>"",COUNTIFS('Risk Controls'!$A:$A,$P14,'Risk Controls'!$H:$H,"<>")=0),"Effectiveness not verified",IF(AND($Q14=3,$Z14=""),"Disclosure reference missing",IF(AND(LEFT($W14,3)="Yes",COUNTIF('Benefit-Risk'!$A:$A,$A14)=0),"Benefit-risk record missing","Complete"))))))))) -> Complete | Y14: N | AA14: Closed
A15: HZ-11 | B15: Durable pump enclosure - cleaning between patients | C15: Biological - cross-contamination | D15: The enclosure is wiped with a disinfectant not on the validated list; the material at a moulded joint degrades and retains residue and microbial load that the next clean does not remove. | E15: Residue and microbial load are transferred between patients. | F15: Cross-infection. | G15: 1, 11.1, 11.2 | H15: 3 | I15: 2 | J15: 3 | K15: Cleaning validation CV-03; material compatibility test MC-11 over 200 cycles. | L15: =IF($H15="","",IF($H15=0,"n/e",INDEX(Scales!$B$32:$F$36,6-$H15,6-$I15))) -> 1 | M15: =IF($L15="","",IF($L15="n/e",IF($J15>=3,"Not acceptable (S only)","Acceptable (S only)"),INDEX(Scales!$B$42:$F$46,6-$L15,$J15))) -> Acceptable | N15: =IF(OR($L15="",$L15="n/e"),"",$L15*$J15) -> 3 | O15: =IF($M15="","",IF(LEFT($M15,3)="Not","Yes - Clause 7.1","Consider AFAP")) -> Consider AFAP | P15: RC-11 | Q15: 3 | R15: 3 | S15: 2 | T15: 3 | U15: =IF($R15="","",IF($R15=0,"n/e",INDEX(Scales!$B$32:$F$36,6-$R15,6-$S15))) -> 1 | V15: =IF($U15="","",IF($U15="n/e",IF($T15>=3,"Not acceptable (S only)","Acceptable (S only)"),INDEX(Scales!$B$42:$F$46,6-$U15,$T15))) -> Acceptable | W15: =IF($V15="","",IF(LEFT($V15,3)="Not","Yes - Clause 7.4","No")) -> No | X15: =IF($A15="","",IF($G15="","GSPR link missing",IF($K15="","Basis for estimate missing",IF(AND(LEFT($O15,3)="Yes",$P15=""),"Risk control missing",IF(AND($P15<>"",COUNTIF('Risk Controls'!$A:$A,$P15)=0),"Control not on Risk Controls",IF(AND($P15<>"",$R15=""),"Residual risk not estimated",IF(AND($P15<>"",COUNTIFS('Risk Controls'!$A:$A,$P15,'Risk Controls'!$H:$H,"<>")=0),"Effectiveness not verified",IF(AND($Q15=3,$Z15=""),"Disclosure reference missing",IF(AND(LEFT($W15,3)="Yes",COUNTIF('Benefit-Risk'!$A:$A,$A15)=0),"Benefit-risk record missing","Complete"))))))))) -> Complete | Y15: N | Z15: IFU section 7.3; label symbol | AA15: Closed
A16: HZ-12 | B16: Administration set patient connector | C16: Energy - misconnection | D16: The set terminates in a connector that will physically mate with an enteral feeding port, and both routes are present at the bedside. | E16: An enteral route is connected to an intravenous port, or the reverse. | F16: Wrong-route administration: death. | G16: 1, 4, 14.1 | H16: 2 | I16: 5 | J16: 5 | K16: Connector conformance test CC-02 to ISO 80369-3 and -7; published wrong-route incident literature. | L16: =IF($H16="","",IF($H16=0,"n/e",INDEX(Scales!$B$32:$F$36,6-$H16,6-$I16))) -> 2 | M16: =IF($L16="","",IF($L16="n/e",IF($J16>=3,"Not acceptable (S only)","Acceptable (S only)"),INDEX(Scales!$B$42:$F$46,6-$L16,$J16))) -> Not acceptable | N16: =IF(OR($L16="",$L16="n/e"),"",$L16*$J16) -> 10 | O16: =IF($M16="","",IF(LEFT($M16,3)="Not","Yes - Clause 7.1","Consider AFAP")) -> Yes - Clause 7.1 | P16: RC-12 | Q16: 1 | R16: 1 | S16: 5 | T16: 5 | U16: =IF($R16="","",IF($R16=0,"n/e",INDEX(Scales!$B$32:$F$36,6-$R16,6-$S16))) -> 1 | V16: =IF($U16="","",IF($U16="n/e",IF($T16>=3,"Not acceptable (S only)","Acceptable (S only)"),INDEX(Scales!$B$42:$F$46,6-$U16,$T16))) -> Not acceptable | W16: =IF($V16="","",IF(LEFT($V16,3)="Not","Yes - Clause 7.4","No")) -> Yes - Clause 7.4 | X16: =IF($A16="","",IF($G16="","GSPR link missing",IF($K16="","Basis for estimate missing",IF(AND(LEFT($O16,3)="Yes",$P16=""),"Risk control missing",IF(AND($P16<>"",COUNTIF('Risk Controls'!$A:$A,$P16)=0),"Control not on Risk Controls",IF(AND($P16<>"",$R16=""),"Residual risk not estimated",IF(AND($P16<>"",COUNTIFS('Risk Controls'!$A:$A,$P16,'Risk Controls'!$H:$H,"<>")=0),"Effectiveness not verified",IF(AND($Q16=3,$Z16=""),"Disclosure reference missing",IF(AND(LEFT($W16,3)="Yes",COUNTIF('Benefit-Risk'!$A:$A,$A16)=0),"Benefit-risk record missing","Complete"))))))))) -> Complete | Y16: N | AA16: Closed
A17: HZ-13 | B17: Transport and storage | C17: Environmental - temperature | D17: The device is left in a vehicle overnight below the specified storage range; the display and battery fall out of specification and the device fails its power-on self-test. | E17: Therapy cannot be started when it is needed. | F17: Delay of therapy. | G17: 1, 7, 14.2(b), 23.4 | H17: 3 | I17: 3 | J17: 2 | K17: Environmental test ET-07; transport simulation TS-02. | L17: =IF($H17="","",IF($H17=0,"n/e",INDEX(Scales!$B$32:$F$36,6-$H17,6-$I17))) -> 2 | M17: =IF($L17="","",IF($L17="n/e",IF($J17>=3,"Not acceptable (S only)","Acceptable (S only)"),INDEX(Scales!$B$42:$F$46,6-$L17,$J17))) -> Acceptable | N17: =IF(OR($L17="",$L17="n/e"),"",$L17*$J17) -> 4 | O17: =IF($M17="","",IF(LEFT($M17,3)="Not","Yes - Clause 7.1","Consider AFAP")) -> Consider AFAP | P17: RC-13 | Q17: 3 | R17: 3 | S17: 3 | T17: 2 | U17: =IF($R17="","",IF($R17=0,"n/e",INDEX(Scales!$B$32:$F$36,6-$R17,6-$S17))) -> 2 | V17: =IF($U17="","",IF($U17="n/e",IF($T17>=3,"Not acceptable (S only)","Acceptable (S only)"),INDEX(Scales!$B$42:$F$46,6-$U17,$T17))) -> Acceptable | W17: =IF($V17="","",IF(LEFT($V17,3)="Not","Yes - Clause 7.4","No")) -> No | X17: =IF($A17="","",IF($G17="","GSPR link missing",IF($K17="","Basis for estimate missing",IF(AND(LEFT($O17,3)="Yes",$P17=""),"Risk control missing",IF(AND($P17<>"",COUNTIF('Risk Controls'!$A:$A,$P17)=0),"Control not on Risk Controls",IF(AND($P17<>"",$R17=""),"Residual risk not estimated",IF(AND($P17<>"",COUNTIFS('Risk Controls'!$A:$A,$P17,'Risk Controls'!$H:$H,"<>")=0),"Effectiveness not verified",IF(AND($Q17=3,$Z17=""),"Disclosure reference missing",IF(AND(LEFT($W17,3)="Yes",COUNTIF('Benefit-Risk'!$A:$A,$A17)=0),"Benefit-risk record missing","Complete"))))))))) -> Complete | Y17: N | Z17: IFU section 4.1; carton label | AA17: Closed
A18: HZ-14 | B18: Disposal of the used administration set | C18: Environmental and biological - third-party exposure | D18: A home user disposes of a set holding residual cytotoxic drug in general household waste; a carer or waste handler contacts the residue. | E18: A third party is exposed to cytotoxic residue. | F18: Chemical injury to a carer or waste handler. | G18: 1, 14.7, 23.4 | H18: 3 | I18: 2 | J18: 3 | K18: Residual volume measurement RV-01; carer interviews in use-related risk analysis URA-14. | L18: =IF($H18="","",IF($H18=0,"n/e",INDEX(Scales!$B$32:$F$36,6-$H18,6-$I18))) -> 1 | M18: =IF($L18="","",IF($L18="n/e",IF($J18>=3,"Not acceptable (S only)","Acceptable (S only)"),INDEX(Scales!$B$42:$F$46,6-$L18,$J18))) -> Acceptable | N18: =IF(OR($L18="",$L18="n/e"),"",$L18*$J18) -> 3 | O18: =IF($M18="","",IF(LEFT($M18,3)="Not","Yes - Clause 7.1","Consider AFAP")) -> Consider AFAP | P18: RC-14 | Q18: 2 | R18: 2 | S18: 2 | T18: 3 | U18: =IF($R18="","",IF($R18=0,"n/e",INDEX(Scales!$B$32:$F$36,6-$R18,6-$S18))) -> 1 | V18: =IF($U18="","",IF($U18="n/e",IF($T18>=3,"Not acceptable (S only)","Acceptable (S only)"),INDEX(Scales!$B$42:$F$46,6-$U18,$T18))) -> Acceptable | W18: =IF($V18="","",IF(LEFT($V18,3)="Not","Yes - Clause 7.4","No")) -> No | X18: =IF($A18="","",IF($G18="","GSPR link missing",IF($K18="","Basis for estimate missing",IF(AND(LEFT($O18,3)="Yes",$P18=""),"Risk control missing",IF(AND($P18<>"",COUNTIF('Risk Controls'!$A:$A,$P18)=0),"Control not on Risk Controls",IF(AND($P18<>"",$R18=""),"Residual risk not estimated",IF(AND($P18<>"",COUNTIFS('Risk Controls'!$A:$A,$P18,'Risk Controls'!$H:$H,"<>")=0),"Effectiveness not verified",IF(AND($Q18=3,$Z18=""),"Disclosure reference missing",IF(AND(LEFT($W18,3)="Yes",COUNTIF('Benefit-Risk'!$A:$A,$A18)=0),"Benefit-risk record missing","Complete"))))))))) -> Complete | Y18: N | Z18: IFU section 9; disposal pictogram | AA18: Open
A19: HZ-15 | B19: Pumping mechanism | C19: Pump failure | D19: Pump fails. | E19: Pump failure. | F19: Harm to patient. | H19: 2 | I19: 2 | J19: 3 | L19: =IF($H19="","",IF($H19=0,"n/e",INDEX(Scales!$B$32:$F$36,6-$H19,6-$I19))) -> 1 | M19: =IF($L19="","",IF($L19="n/e",IF($J19>=3,"Not acceptable (S only)","Acceptable (S only)"),INDEX(Scales!$B$42:$F$46,6-$L19,$J19))) -> Acceptable | N19: =IF(OR($L19="",$L19="n/e"),"",$L19*$J19) -> 3 | O19: =IF($M19="","",IF(LEFT($M19,3)="Not","Yes - Clause 7.1","Consider AFAP")) -> Consider AFAP | U19: =IF($R19="","",IF($R19=0,"n/e",INDEX(Scales!$B$32:$F$36,6-$R19,6-$S19))) | V19: =IF($U19="","",IF($U19="n/e",IF($T19>=3,"Not acceptable (S only)","Acceptable (S only)"),INDEX(Scales!$B$42:$F$46,6-$U19,$T19))) | W19: =IF($V19="","",IF(LEFT($V19,3)="Not","Yes - Clause 7.4","No")) | X19: =IF($A19="","",IF($G19="","GSPR link missing",IF($K19="","Basis for estimate missing",IF(AND(LEFT($O19,3)="Yes",$P19=""),"Risk control missing",IF(AND($P19<>"",COUNTIF('Risk Controls'!$A:$A,$P19)=0),"Control not on Risk Controls",IF(AND($P19<>"",$R19=""),"Residual risk not estimated",IF(AND($P19<>"",COUNTIFS('Risk Controls'!$A:$A,$P19,'Risk Controls'!$H:$H,"<>")=0),"Effectiveness not verified",IF(AND($Q19=3,$Z19=""),"Disclosure reference missing",IF(AND(LEFT($W19,3)="Yes",COUNTIF('Benefit-Risk'!$A:$A,$A19)=0),"Benefit-risk record missing","Complete"))))))))) -> GSPR link missing | AA19: Open
A20: HZ-16 | B20: User interface - alarm silence | C20: Use error - alarm silenced | D20: User silences the alarm. | E20: Alarm silenced. | F20: Delay of therapy. | G20: 1 | H20: 5 | I20: 5 | J20: 4 | K20: Engineering judgement. | L20: =IF($H20="","",IF($H20=0,"n/e",INDEX(Scales!$B$32:$F$36,6-$H20,6-$I20))) -> 5 | M20: =IF($L20="","",IF($L20="n/e",IF($J20>=3,"Not acceptable (S only)","Acceptable (S only)"),INDEX(Scales!$B$42:$F$46,6-$L20,$J20))) -> Not acceptable | N20: =IF(OR($L20="",$L20="n/e"),"",$L20*$J20) -> 20 | O20: =IF($M20="","",IF(LEFT($M20,3)="Not","Yes - Clause 7.1","Consider AFAP")) -> Yes - Clause 7.1 | P20: RC-16 | Q20: 3 | R20: 1 | S20: 1 | T20: 4 | U20: =IF($R20="","",IF($R20=0,"n/e",INDEX(Scales!$B$32:$F$36,6-$R20,6-$S20))) -> 1 | V20: =IF($U20="","",IF($U20="n/e",IF($T20>=3,"Not acceptable (S only)","Acceptable (S only)"),INDEX(Scales!$B$42:$F$46,6-$U20,$T20))) -> Acceptable | W20: =IF($V20="","",IF(LEFT($V20,3)="Not","Yes - Clause 7.4","No")) -> No | X20: =IF($A20="","",IF($G20="","GSPR link missing",IF($K20="","Basis for estimate missing",IF(AND(LEFT($O20,3)="Yes",$P20=""),"Risk control missing",IF(AND($P20<>"",COUNTIF('Risk Controls'!$A:$A,$P20)=0),"Control not on Risk Controls",IF(AND($P20<>"",$R20=""),"Residual risk not estimated",IF(AND($P20<>"",COUNTIFS('Risk Controls'!$A:$A,$P20,'Risk Controls'!$H:$H,"<>")=0),"Effectiveness not verified",IF(AND($Q20=3,$Z20=""),"Disclosure reference missing",IF(AND(LEFT($W20,3)="Yes",COUNTIF('Benefit-Risk'!$A:$A,$A20)=0),"Benefit-risk record missing","Complete"))))))))) -> Effectiveness not verified | Y20: N | AA20: Closed
L21: =IF($H21="","",IF($H21=0,"n/e",INDEX(Scales!$B$32:$F$36,6-$H21,6-$I21))) | M21: =IF($L21="","",IF($L21="n/e",IF($J21>=3,"Not acceptable (S only)","Acceptable (S only)"),INDEX(Scales!$B$42:$F$46,6-$L21,$J21))) | N21: =IF(OR($L21="",$L21="n/e"),"",$L21*$J21) | O21: =IF($M21="","",IF(LEFT($M21,3)="Not","Yes - Clause 7.1","Consider AFAP")) | U21: =IF($R21="","",IF($R21=0,"n/e",INDEX(Scales!$B$32:$F$36,6-$R21,6-$S21))) | V21: =IF($U21="","",IF($U21="n/e",IF($T21>=3,"Not acceptable (S only)","Acceptable (S only)"),INDEX(Scales!$B$42:$F$46,6-$U21,$T21))) | W21: =IF($V21="","",IF(LEFT($V21,3)="Not","Yes - Clause 7.4","No")) | X21: =IF($A21="","",IF($G21="","GSPR link missing",IF($K21="","Basis for estimate missing",IF(AND(LEFT($O21,3)="Yes",$P21=""),"Risk control missing",IF(AND($P21<>"",COUNTIF('Risk Controls'!$A:$A,$P21)=0),"Control not on Risk Controls",IF(AND($P21<>"",$R21=""),"Residual risk not estimated",IF(AND($P21<>"",COUNTIFS('Risk Controls'!$A:$A,$P21,'Risk Controls'!$H:$H,"<>")=0),"Effectiveness not verified",IF(AND($Q21=3,$Z21=""),"Disclosure reference missing",IF(AND(LEFT($W21,3)="Yes",COUNTIF('Benefit-Risk'!$A:$A,$A21)=0),"Benefit-risk record missing","Complete")))))))))
L22: =IF($H22="","",IF($H22=0,"n/e",INDEX(Scales!$B$32:$F$36,6-$H22,6-$I22))) | M22: =IF($L22="","",IF($L22="n/e",IF($J22>=3,"Not acceptable (S only)","Acceptable (S only)"),INDEX(Scales!$B$42:$F$46,6-$L22,$J22))) | N22: =IF(OR($L22="",$L22="n/e"),"",$L22*$J22) | O22: =IF($M22="","",IF(LEFT($M22,3)="Not","Yes - Clause 7.1","Consider AFAP")) | U22: =IF($R22="","",IF($R22=0,"n/e",INDEX(Scales!$B$32:$F$36,6-$R22,6-$S22))) | V22: =IF($U22="","",IF($U22="n/e",IF($T22>=3,"Not acceptable (S only)","Acceptable (S only)"),INDEX(Scales!$B$42:$F$46,6-$U22,$T22))) | W22: =IF($V22="","",IF(LEFT($V22,3)="Not","Yes - Clause 7.4","No")) | X22: =IF($A22="","",IF($G22="","GSPR link missing",IF($K22="","Basis for estimate missing",IF(AND(LEFT($O22,3)="Yes",$P22=""),"Risk control missing",IF(AND($P22<>"",COUNTIF('Risk Controls'!$A:$A,$P22)=0),"Control not on Risk Controls",IF(AND($P22<>"",$R22=""),"Residual risk not estimated",IF(AND($P22<>"",COUNTIFS('Risk Controls'!$A:$A,$P22,'Risk Controls'!$H:$H,"<>")=0),"Effectiveness not verified",IF(AND($Q22=3,$Z22=""),"Disclosure reference missing",IF(AND(LEFT($W22,3)="Yes",COUNTIF('Benefit-Risk'!$A:$A,$A22)=0),"Benefit-risk record missing","Complete")))))))))
L23: =IF($H23="","",IF($H23=0,"n/e",INDEX(Scales!$B$32:$F$36,6-$H23,6-$I23))) | M23: =IF($L23="","",IF($L23="n/e",IF($J23>=3,"Not acceptable (S only)","Acceptable (S only)"),INDEX(Scales!$B$42:$F$46,6-$L23,$J23))) | N23: =IF(OR($L23="",$L23="n/e"),"",$L23*$J23) | O23: =IF($M23="","",IF(LEFT($M23,3)="Not","Yes - Clause 7.1","Consider AFAP")) | U23: =IF($R23="","",IF($R23=0,"n/e",INDEX(Scales!$B$32:$F$36,6-$R23,6-$S23))) | V23: =IF($U23="","",IF($U23="n/e",IF($T23>=3,"Not acceptable (S only)","Acceptable (S only)"),INDEX(Scales!$B$42:$F$46,6-$U23,$T23))) | W23: =IF($V23="","",IF(LEFT($V23,3)="Not","Yes - Clause 7.4","No")) | X23: =IF($A23="","",IF($G23="","GSPR link missing",IF($K23="","Basis for estimate missing",IF(AND(LEFT($O23,3)="Yes",$P23=""),"Risk control missing",IF(AND($P23<>"",COUNTIF('Risk Controls'!$A:$A,$P23)=0),"Control not on Risk Controls",IF(AND($P23<>"",$R23=""),"Residual risk not estimated",IF(AND($P23<>"",COUNTIFS('Risk Controls'!$A:$A,$P23,'Risk Controls'!$H:$H,"<>")=0),"Effectiveness not verified",IF(AND($Q23=3,$Z23=""),"Disclosure reference missing",IF(AND(LEFT($W23,3)="Yes",COUNTIF('Benefit-Risk'!$A:$A,$A23)=0),"Benefit-risk record missing","Complete")))))))))
L24: =IF($H24="","",IF($H24=0,"n/e",INDEX(Scales!$B$32:$F$36,6-$H24,6-$I24))) | M24: =IF($L24="","",IF($L24="n/e",IF($J24>=3,"Not acceptable (S only)","Acceptable (S only)"),INDEX(Scales!$B$42:$F$46,6-$L24,$J24))) | N24: =IF(OR($L24="",$L24="n/e"),"",$L24*$J24) | O24: =IF($M24="","",IF(LEFT($M24,3)="Not","Yes - Clause 7.1","Consider AFAP")) | U24: =IF($R24="","",IF($R24=0,"n/e",INDEX(Scales!$B$32:$F$36,6-$R24,6-$S24))) | V24: =IF($U24="","",IF($U24="n/e",IF($T24>=3,"Not acceptable (S only)","Acceptable (S only)"),INDEX(Scales!$B$42:$F$46,6-$U24,$T24))) | W24: =IF($V24="","",IF(LEFT($V24,3)="Not","Yes - Clause 7.4","No")) | X24: =IF($A24="","",IF($G24="","GSPR link missing",IF($K24="","Basis for estimate missing",IF(AND(LEFT($O24,3)="Yes",$P24=""),"Risk control missing",IF(AND($P24<>"",COUNTIF('Risk Controls'!$A:$A,$P24)=0),"Control not on Risk Controls",IF(AND($P24<>"",$R24=""),"Residual risk not estimated",IF(AND($P24<>"",COUNTIFS('Risk Controls'!$A:$A,$P24,'Risk Controls'!$H:$H,"<>")=0),"Effectiveness not verified",IF(AND($Q24=3,$Z24=""),"Disclosure reference missing",IF(AND(LEFT($W24,3)="Yes",COUNTIF('Benefit-Risk'!$A:$A,$A24)=0),"Benefit-risk record missing","Complete")))))))))
L25: =IF($H25="","",IF($H25=0,"n/e",INDEX(Scales!$B$32:$F$36,6-$H25,6-$I25))) | M25: =IF($L25="","",IF($L25="n/e",IF($J25>=3,"Not acceptable (S only)","Acceptable (S only)"),INDEX(Scales!$B$42:$F$46,6-$L25,$J25))) | N25: =IF(OR($L25="",$L25="n/e"),"",$L25*$J25) | O25: =IF($M25="","",IF(LEFT($M25,3)="Not","Yes - Clause 7.1","Consider AFAP")) | U25: =IF($R25="","",IF($R25=0,"n/e",INDEX(Scales!$B$32:$F$36,6-$R25,6-$S25))) | V25: =IF($U25="","",IF($U25="n/e",IF($T25>=3,"Not acceptable (S only)","Acceptable (S only)"),INDEX(Scales!$B$42:$F$46,6-$U25,$T25))) | W25: =IF($V25="","",IF(LEFT($V25,3)="Not","Yes - Clause 7.4","No")) | X25: =IF($A25="","",IF($G25="","GSPR link missing",IF($K25="","Basis for estimate missing",IF(AND(LEFT($O25,3)="Yes",$P25=""),"Risk control missing",IF(AND($P25<>"",COUNTIF('Risk Controls'!$A:$A,$P25)=0),"Control not on Risk Controls",IF(AND($P25<>"",$R25=""),"Residual risk not estimated",IF(AND($P25<>"",COUNTIFS('Risk Controls'!$A:$A,$P25,'Risk Controls'!$H:$H,"<>")=0),"Effectiveness not verified",IF(AND($Q25=3,$Z25=""),"Disclosure reference missing",IF(AND(LEFT($W25,3)="Yes",COUNTIF('Benefit-Risk'!$A:$A,$A25)=0),"Benefit-risk record missing","Complete")))))))))
L26: =IF($H26="","",IF($H26=0,"n/e",INDEX(Scales!$B$32:$F$36,6-$H26,6-$I26))) | M26: =IF($L26="","",IF($L26="n/e",IF($J26>=3,"Not acceptable (S only)","Acceptable (S only)"),INDEX(Scales!$B$42:$F$46,6-$L26,$J26))) | N26: =IF(OR($L26="",$L26="n/e"),"",$L26*$J26) | O26: =IF($M26="","",IF(LEFT($M26,3)="Not","Yes - Clause 7.1","Consider AFAP")) | U26: =IF($R26="","",IF($R26=0,"n/e",INDEX(Scales!$B$32:$F$36,6-$R26,6-$S26))) | V26: =IF($U26="","",IF($U26="n/e",IF($T26>=3,"Not acceptable (S only)","Acceptable (S only)"),INDEX(Scales!$B$42:$F$46,6-$U26,$T26))) | W26: =IF($V26="","",IF(LEFT($V26,3)="Not","Yes - Clause 7.4","No")) | X26: =IF($A26="","",IF($G26="","GSPR link missing",IF($K26="","Basis for estimate missing",IF(AND(LEFT($O26,3)="Yes",$P26=""),"Risk control missing",IF(AND($P26<>"",COUNTIF('Risk Controls'!$A:$A,$P26)=0),"Control not on Risk Controls",IF(AND($P26<>"",$R26=""),"Residual risk not estimated",IF(AND($P26<>"",COUNTIFS('Risk Controls'!$A:$A,$P26,'Risk Controls'!$H:$H,"<>")=0),"Effectiveness not verified",IF(AND($Q26=3,$Z26=""),"Disclosure reference missing",IF(AND(LEFT($W26,3)="Yes",COUNTIF('Benefit-Risk'!$A:$A,$A26)=0),"Benefit-risk record missing","Complete")))))))))
L27: =IF($H27="","",IF($H27=0,"n/e",INDEX(Scales!$B$32:$F$36,6-$H27,6-$I27))) | M27: =IF($L27="","",IF($L27="n/e",IF($J27>=3,"Not acceptable (S only)","Acceptable (S only)"),INDEX(Scales!$B$42:$F$46,6-$L27,$J27))) | N27: =IF(OR($L27="",$L27="n/e"),"",$L27*$J27) | O27: =IF($M27="","",IF(LEFT($M27,3)="Not","Yes - Clause 7.1","Consider AFAP")) | U27: =IF($R27="","",IF($R27=0,"n/e",INDEX(Scales!$B$32:$F$36,6-$R27,6-$S27))) | V27: =IF($U27="","",IF($U27="n/e",IF($T27>=3,"Not acceptable (S only)","Acceptable (S only)"),INDEX(Scales!$B$42:$F$46,6-$U27,$T27))) | W27: =IF($V27="","",IF(LEFT($V27,3)="Not","Yes - Clause 7.4","No")) | X27: =IF($A27="","",IF($G27="","GSPR link missing",IF($K27="","Basis for estimate missing",IF(AND(LEFT($O27,3)="Yes",$P27=""),"Risk control missing",IF(AND($P27<>"",COUNTIF('Risk Controls'!$A:$A,$P27)=0),"Control not on Risk Controls",IF(AND($P27<>"",$R27=""),"Residual risk not estimated",IF(AND($P27<>"",COUNTIFS('Risk Controls'!$A:$A,$P27,'Risk Controls'!$H:$H,"<>")=0),"Effectiveness not verified",IF(AND($Q27=3,$Z27=""),"Disclosure reference missing",IF(AND(LEFT($W27,3)="Yes",COUNTIF('Benefit-Risk'!$A:$A,$A27)=0),"Benefit-risk record missing","Complete")))))))))
L28: =IF($H28="","",IF($H28=0,"n/e",INDEX(Scales!$B$32:$F$36,6-$H28,6-$I28))) | M28: =IF($L28="","",IF($L28="n/e",IF($J28>=3,"Not acceptable (S only)","Acceptable (S only)"),INDEX(Scales!$B$42:$F$46,6-$L28,$J28))) | N28: =IF(OR($L28="",$L28="n/e"),"",$L28*$J28) | O28: =IF($M28="","",IF(LEFT($M28,3)="Not","Yes - Clause 7.1","Consider AFAP")) | U28: =IF($R28="","",IF($R28=0,"n/e",INDEX(Scales!$B$32:$F$36,6-$R28,6-$S28))) | V28: =IF($U28="","",IF($U28="n/e",IF($T28>=3,"Not acceptable (S only)","Acceptable (S only)"),INDEX(Scales!$B$42:$F$46,6-$U28,$T28))) | W28: =IF($V28="","",IF(LEFT($V28,3)="Not","Yes - Clause 7.4","No")) | X28: =IF($A28="","",IF($G28="","GSPR link missing",IF($K28="","Basis for estimate missing",IF(AND(LEFT($O28,3)="Yes",$P28=""),"Risk control missing",IF(AND($P28<>"",COUNTIF('Risk Controls'!$A:$A,$P28)=0),"Control not on Risk Controls",IF(AND($P28<>"",$R28=""),"Residual risk not estimated",IF(AND($P28<>"",COUNTIFS('Risk Controls'!$A:$A,$P28,'Risk Controls'!$H:$H,"<>")=0),"Effectiveness not verified",IF(AND($Q28=3,$Z28=""),"Disclosure reference missing",IF(AND(LEFT($W28,3)="Yes",COUNTIF('Benefit-Risk'!$A:$A,$A28)=0),"Benefit-risk record missing","Complete")))))))))
L29: =IF($H29="","",IF($H29=0,"n/e",INDEX(Scales!$B$32:$F$36,6-$H29,6-$I29))) | M29: =IF($L29="","",IF($L29="n/e",IF($J29>=3,"Not acceptable (S only)","Acceptable (S only)"),INDEX(Scales!$B$42:$F$46,6-$L29,$J29))) | N29: =IF(OR($L29="",$L29="n/e"),"",$L29*$J29) | O29: =IF($M29="","",IF(LEFT($M29,3)="Not","Yes - Clause 7.1","Consider AFAP")) | U29: =IF($R29="","",IF($R29=0,"n/e",INDEX(Scales!$B$32:$F$36,6-$R29,6-$S29))) | V29: =IF($U29="","",IF($U29="n/e",IF($T29>=3,"Not acceptable (S only)","Acceptable (S only)"),INDEX(Scales!$B$42:$F$46,6-$U29,$T29))) | W29: =IF($V29="","",IF(LEFT($V29,3)="Not","Yes - Clause 7.4","No")) | X29: =IF($A29="","",IF($G29="","GSPR link missing",IF($K29="","Basis for estimate missing",IF(AND(LEFT($O29,3)="Yes",$P29=""),"Risk control missing",IF(AND($P29<>"",COUNTIF('Risk Controls'!$A:$A,$P29)=0),"Control not on Risk Controls",IF(AND($P29<>"",$R29=""),"Residual risk not estimated",IF(AND($P29<>"",COUNTIFS('Risk Controls'!$A:$A,$P29,'Risk Controls'!$H:$H,"<>")=0),"Effectiveness not verified",IF(AND($Q29=3,$Z29=""),"Disclosure reference missing",IF(AND(LEFT($W29,3)="Yes",COUNTIF('Benefit-Risk'!$A:$A,$A29)=0),"Benefit-risk record missing","Complete")))))))))
L30: =IF($H30="","",IF($H30=0,"n/e",INDEX(Scales!$B$32:$F$36,6-$H30,6-$I30))) | M30: =IF($L30="","",IF($L30="n/e",IF($J30>=3,"Not acceptable (S only)","Acceptable (S only)"),INDEX(Scales!$B$42:$F$46,6-$L30,$J30))) | N30: =IF(OR($L30="",$L30="n/e"),"",$L30*$J30) | O30: =IF($M30="","",IF(LEFT($M30,3)="Not","Yes - Clause 7.1","Consider AFAP")) | U30: =IF($R30="","",IF($R30=0,"n/e",INDEX(Scales!$B$32:$F$36,6-$R30,6-$S30))) | V30: =IF($U30="","",IF($U30="n/e",IF($T30>=3,"Not acceptable (S only)","Acceptable (S only)"),INDEX(Scales!$B$42:$F$46,6-$U30,$T30))) | W30: =IF($V30="","",IF(LEFT($V30,3)="Not","Yes - Clause 7.4","No")) | X30: =IF($A30="","",IF($G30="","GSPR link missing",IF($K30="","Basis for estimate missing",IF(AND(LEFT($O30,3)="Yes",$P30=""),"Risk control missing",IF(AND($P30<>"",COUNTIF('Risk Controls'!$A:$A,$P30)=0),"Control not on Risk Controls",IF(AND($P30<>"",$R30=""),"Residual risk not estimated",IF(AND($P30<>"",COUNTIFS('Risk Controls'!$A:$A,$P30,'Risk Controls'!$H:$H,"<>")=0),"Effectiveness not verified",IF(AND($Q30=3,$Z30=""),"Disclosure reference missing",IF(AND(LEFT($W30,3)="Yes",COUNTIF('Benefit-Risk'!$A:$A,$A30)=0),"Benefit-risk record missing","Complete")))))))))
L31: =IF($H31="","",IF($H31=0,"n/e",INDEX(Scales!$B$32:$F$36,6-$H31,6-$I31))) | M31: =IF($L31="","",IF($L31="n/e",IF($J31>=3,"Not acceptable (S only)","Acceptable (S only)"),INDEX(Scales!$B$42:$F$46,6-$L31,$J31))) | N31: =IF(OR($L31="",$L31="n/e"),"",$L31*$J31) | O31: =IF($M31="","",IF(LEFT($M31,3)="Not","Yes - Clause 7.1","Consider AFAP")) | U31: =IF($R31="","",IF($R31=0,"n/e",INDEX(Scales!$B$32:$F$36,6-$R31,6-$S31))) | V31: =IF($U31="","",IF($U31="n/e",IF($T31>=3,"Not acceptable (S only)","Acceptable (S only)"),INDEX(Scales!$B$42:$F$46,6-$U31,$T31))) | W31: =IF($V31="","",IF(LEFT($V31,3)="Not","Yes - Clause 7.4","No")) | X31: =IF($A31="","",IF($G31="","GSPR link missing",IF($K31="","Basis for estimate missing",IF(AND(LEFT($O31,3)="Yes",$P31=""),"Risk control missing",IF(AND($P31<>"",COUNTIF('Risk Controls'!$A:$A,$P31)=0),"Control not on Risk Controls",IF(AND($P31<>"",$R31=""),"Residual risk not estimated",IF(AND($P31<>"",COUNTIFS('Risk Controls'!$A:$A,$P31,'Risk Controls'!$H:$H,"<>")=0),"Effectiveness not verified",IF(AND($Q31=3,$Z31=""),"Disclosure reference missing",IF(AND(LEFT($W31,3)="Yes",COUNTIF('Benefit-Risk'!$A:$A,$A31)=0),"Benefit-risk record missing","Complete")))))))))
L32: =IF($H32="","",IF($H32=0,"n/e",INDEX(Scales!$B$32:$F$36,6-$H32,6-$I32))) | M32: =IF($L32="","",IF($L32="n/e",IF($J32>=3,"Not acceptable (S only)","Acceptable (S only)"),INDEX(Scales!$B$42:$F$46,6-$L32,$J32))) | N32: =IF(OR($L32="",$L32="n/e"),"",$L32*$J32) | O32: =IF($M32="","",IF(LEFT($M32,3)="Not","Yes - Clause 7.1","Consider AFAP")) | U32: =IF($R32="","",IF($R32=0,"n/e",INDEX(Scales!$B$32:$F$36,6-$R32,6-$S32))) | V32: =IF($U32="","",IF($U32="n/e",IF($T32>=3,"Not acceptable (S only)","Acceptable (S only)"),INDEX(Scales!$B$42:$F$46,6-$U32,$T32))) | W32: =IF($V32="","",IF(LEFT($V32,3)="Not","Yes - Clause 7.4","No")) | X32: =IF($A32="","",IF($G32="","GSPR link missing",IF($K32="","Basis for estimate missing",IF(AND(LEFT($O32,3)="Yes",$P32=""),"Risk control missing",IF(AND($P32<>"",COUNTIF('Risk Controls'!$A:$A,$P32)=0),"Control not on Risk Controls",IF(AND($P32<>"",$R32=""),"Residual risk not estimated",IF(AND($P32<>"",COUNTIFS('Risk Controls'!$A:$A,$P32,'Risk Controls'!$H:$H,"<>")=0),"Effectiveness not verified",IF(AND($Q32=3,$Z32=""),"Disclosure reference missing",IF(AND(LEFT($W32,3)="Yes",COUNTIF('Benefit-Risk'!$A:$A,$A32)=0),"Benefit-risk record missing","Complete")))))))))
